<mujoco model="g1">
  <compiler angle="radian" meshdir="meshes/" autolimits="true" discardvisual="false"/>
  <statistic meansize="0.144785" extent="1.23314" center="0.025392 2.0634e-05 -0.245975"/>
  <default>
    <joint damping="0.5" armature="0.01" frictionloss="0.1"/>
  </default>
  <asset>
    <mesh name="pelvis" file="pelvis.STL"/>
    <mesh name="pelvis_contour_link" file="pelvis_contour_link.STL"/>
    <mesh name="left_hip_pitch_link" file="left_hip_pitch_link.STL"/>
    <mesh name="left_hip_roll_link" file="left_hip_roll_link.STL"/>
    <mesh name="left_hip_yaw_link" file="left_hip_yaw_link.STL"/>
    <mesh name="left_knee_link" file="left_knee_link.STL"/>
    <mesh name="left_ankle_pitch_link" file="left_ankle_pitch_link.STL"/>
    <mesh name="left_ankle_roll_link" file="left_ankle_roll_link.STL"/>
    <mesh name="right_hip_pitch_link" file="right_hip_pitch_link.STL"/>
    <mesh name="right_hip_roll_link" file="right_hip_roll_link.STL"/>
    <mesh name="right_hip_yaw_link" file="right_hip_yaw_link.STL"/>
    <mesh name="right_knee_link" file="right_knee_link.STL"/>
    <mesh name="right_ankle_pitch_link" file="right_ankle_pitch_link.STL"/>
    <mesh name="right_ankle_roll_link" file="right_ankle_roll_link.STL"/>
    <mesh name="torso_link" file="torso_link.STL"/>
    <mesh name="head_link" file="head_link.STL"/>
    <mesh name="left_shoulder_pitch_link" file="left_shoulder_pitch_link.STL"/>
    <mesh name="left_shoulder_roll_link" file="left_shoulder_roll_link.STL"/>
    <mesh name="left_shoulder_yaw_link" file="left_shoulder_yaw_link.STL"/>
    <mesh name="left_elbow_pitch_link" file="left_elbow_pitch_link.STL"/>
    <mesh name="left_elbow_roll_link" file="left_elbow_roll_link.STL"/>
    <mesh name="right_shoulder_pitch_link" file="right_shoulder_pitch_link.STL"/>
    <mesh name="right_shoulder_roll_link" file="right_shoulder_roll_link.STL"/>
    <mesh name="right_shoulder_yaw_link" file="right_shoulder_yaw_link.STL"/>
    <mesh name="right_elbow_pitch_link" file="right_elbow_pitch_link.STL"/>
    <mesh name="right_elbow_roll_link" file="right_elbow_roll_link.STL"/>
    <mesh name="logo_link" file="logo_link.STL"/>
    <mesh name="left_palm_link" file="left_palm_link.STL"/>
    <mesh name="left_zero_link" file="left_zero_link.STL"/>
    <mesh name="left_one_link" file="left_one_link.STL"/>
    <mesh name="left_two_link" file="left_two_link.STL"/>
    <mesh name="left_three_link" file="left_three_link.STL"/>
    <mesh name="left_four_link" file="left_four_link.STL"/>
    <mesh name="left_five_link" file="left_five_link.STL"/>
    <mesh name="left_six_link" file="left_six_link.STL"/>
    <mesh name="right_palm_link" file="right_palm_link.STL"/>
    <mesh name="right_zero_link" file="right_zero_link.STL"/>
    <mesh name="right_one_link" file="right_one_link.STL"/>
    <mesh name="right_two_link" file="right_two_link.STL"/>
    <mesh name="right_three_link" file="right_three_link.STL"/>
    <mesh name="right_four_link" file="right_four_link.STL"/>
    <mesh name="right_five_link" file="right_five_link.STL"/>
    <mesh name="right_six_link" file="right_six_link.STL"/>
  </asset>
  <worldbody>
            <body name="right_elbow_roll_link" pos="0 0 0" quat="0 0.7 0 .7">
              <inertial pos="0.133814 -0.00147121 0.000265832" quat="0.7 0.7 0 0" mass="0.050826" diaginertia="0.00239763 0.00226639 0.000285577"/>
              <joint name="right_elbow_roll_joint" pos="0 0 0" axis="1 0 0" range="-0.0143 0.0143"/>
              <geom type="mesh" contype="0" conaffinity="0" group="1" density="0" rgba="0.7 0.7 0.7 1" mesh="right_elbow_roll_link"/>
              <geom type="mesh" rgba="0.7 0.7 0.7 1" mesh="right_elbow_roll_link"/>
              <geom pos="0.12 0 0" type="mesh" contype="0" conaffinity="0" group="1" density="0" rgba="0.7 0.7 0.7 1" mesh="right_palm_link"/>
              <geom pos="0.12 0 0" type="mesh" rgba="0.7 0.7 0.7 1" mesh="right_palm_link"/>
              <body name="right_zero_link" pos="0.17 0 0">
                <inertial pos="-0.0260466 0.00877511 1.08605e-05" quat="0.381376 0.59241 -0.389884 0.592953" mass="0.0509893" diaginertia="8.68047e-06 7.23365e-06 4.58058e-06"/>
                <joint name="right_zero_joint" pos="0 0 0" axis="0 1 0" range="-0.523598 0.523598"/>
                <geom type="mesh" contype="0" conaffinity="0" group="1" density="0" rgba="0.7 0.7 0.7 1" mesh="right_zero_link"/>
                <body name="right_one_link" pos="-0.026525 0.0188 -5e-05">
                  <inertial pos="-0.00181538 0.0327057 -0.000185871" quat="0.698199 0.701646 0.116289 -0.0817825" mass="0.047762" diaginertia="8.03051e-06 7.8455e-06 3.65282e-06"/>
                  <joint name="right_one_joint" pos="0 0 0" axis="0 0 1" range="-1.2 1"/>
                  <geom type="mesh" contype="0" conaffinity="0" group="1" density="0" rgba="0.7 0.7 0.7 1" mesh="right_one_link"/>
                  <geom size="0.01 0.015 0.01" pos="-0.001 0.032 0" type="box" rgba="0.7 0.7 0.7 1"/>
                  <body name="right_two_link" pos="0 0.0431 0">
                    <inertial pos="-0.00135257 0.0237591 -0.000119669" quat="0.695316 0.717995 0.0263741 0.0180122" mass="0.0138584" diaginertia="2.55338e-06 2.04399e-06 9.3995e-07"/>
                    <joint name="right_two_joint" pos="0 0 0" axis="0 0 1" range="-1.84 0"/>
                    <geom type="mesh" contype="0" conaffinity="0" group="1" density="0" rgba="0.7 0.7 0.7 1" mesh="right_two_link"/>
                    <geom type="mesh" rgba="0.7 0.7 0.7 1" mesh="right_two_link"/>
                  </body>
                </body>
              </body>
              <body name="right_three_link" pos="0.205 -0.004 0.02395">
                <inertial pos="0.0362561 0.0015725 0.000269899" quat="0.45376 0.5397 0.459072 0.540443" mass="0.0488469" diaginertia="8.91742e-06 8.64873e-06 3.8319e-06"/>
                <joint name="right_three_joint" pos="0 0 0" axis="0 0 1" range="-0.3 1.84"/>
                <geom type="mesh" contype="0" conaffinity="0" group="1" density="0" rgba="0.7 0.7 0.7 1" mesh="right_three_link"/>
                <geom type="mesh" rgba="0.7 0.7 0.7 1" mesh="right_three_link"/>
                <body name="right_four_link" pos="0.0471 0.0036 0">
                  <inertial pos="0.0237591 -0.00135257 0.000119669" quat="0.504399 0.526348 0.48905 0.478926" mass="0.0138584" diaginertia="2.55338e-06 2.04399e-06 9.3995e-07"/>
                  <joint name="right_four_joint" pos="0 0 0" axis="0 0 1" range="0 1.84"/>
                  <geom type="mesh" contype="0" conaffinity="0" group="1" density="0" rgba="0.7 0.7 0.7 1" mesh="right_four_link"/>
                  <geom type="mesh" rgba="0.7 0.7 0.7 1" mesh="right_four_link"/>
                </body>
              </body>
              <body name="right_five_link" pos="0.205 -0.004 -0.02395">
                <inertial pos="0.0362561 0.0015725 0.000269899" quat="0.45376 0.5397 0.459072 0.540443" mass="0.0488469" diaginertia="8.91742e-06 8.64873e-06 3.8319e-06"/>
                <joint name="right_five_joint" pos="0 0 0" axis="0 0 1" range="-0.3 1.84"/>
                <geom type="mesh" contype="0" conaffinity="0" group="1" density="0" rgba="0.7 0.7 0.7 1" mesh="right_five_link"/>
                <geom type="mesh" rgba="0.7 0.7 0.7 1" mesh="right_five_link"/>
                <body name="right_six_link" pos="0.0471 0.0036 0">
                  <inertial pos="0.0237591 -0.00135257 0.000119669" quat="0.504399 0.526348 0.48905 0.478926" mass="0.0138584" diaginertia="2.55338e-06 2.04399e-06 9.3995e-07"/>
                  <joint name="right_six_joint" pos="0 0 0" axis="0 0 1" range="0 1.84"/>
                  <geom type="mesh" contype="0" conaffinity="0" group="1" density="0" rgba="0.7 0.7 0.7 1" mesh="right_six_link"/>
                  <geom type="mesh" rgba="0.7 0.7 0.7 1" mesh="right_six_link"/>
                </body>
              </body>
            </body>
  </worldbody>
  <actuator>
    <motor name="right_elbow_roll_joint" joint="right_elbow_roll_joint" ctrllimited="true" ctrlrange="-20 20"/>
    <motor name="right_zero_joint" joint="right_zero_joint" ctrllimited="true" ctrlrange="-0.7 0.7"/>
    <motor name="right_one_joint" joint="right_one_joint" ctrllimited="true" ctrlrange="-0.7 0.7"/>
    <motor name="right_two_joint" joint="right_two_joint" ctrllimited="true" ctrlrange="-0.7 0.7"/>
    <motor name="right_three_joint" joint="right_three_joint" ctrllimited="true" ctrlrange="-0.7 0.7"/>
    <motor name="right_four_joint" joint="right_four_joint" ctrllimited="true" ctrlrange="-0.7 0.7"/>
    <motor name="right_five_joint" joint="right_five_joint" ctrllimited="true" ctrlrange="-0.7 0.7"/>
    <motor name="right_six_joint" joint="right_six_joint" ctrllimited="true" ctrlrange="-0.7 0.7"/>
  </actuator>
</mujoco>
